<?xml version="1.0" encoding="utf-8"?>
<!-- This URDF was automatically created by SolidWorks to URDF Exporter! Originally created by Stephen Brawner (brawner@gmail.com) 
     Commit Version: 1.6.0-1-g15f4949  Build Version: 1.6.7594.29634
     For more information, please see http://wiki.ros.org/sw_urdf_exporter -->
<robot
  name="second one">
  <link
    name="base_link">
    <inertial>
      <origin
        xyz="-1.21438856483212E-05 -7.88297985189132E-06 0.0384433351833047"
        rpy="0 0 0" />
      <mass
        value="0.215478194166762" />
      <inertia
        ixx="8.64907439125203E-05"
        ixy="4.34963908748108E-08"
        ixz="7.77088059636832E-09"
        iyy="8.64496606679992E-05"
        iyz="4.75823502430256E-09"
        izz="9.73631709609537E-05" />
    </inertial>
    <visual>
      <origin
        xyz="0 0 0"
        rpy="0 0 0" />
      <geometry>
        <mesh
          filename="package://second one/meshes/base_link.STL" />
      </geometry>
      <material
        name="">
        <color
          rgba="0.792156862745098 0.819607843137255 0.933333333333333 1" />
      </material>
    </visual>
    <collision>
      <origin
        xyz="0 0 0"
        rpy="0 0 0" />
      <geometry>
        <mesh
          filename="package://second one/meshes/base_link.STL" />
      </geometry>
    </collision>
  </link>
  <link
    name="link_1">
    <inertial>
      <origin
        xyz="-0.0598586603355526 -6.56325443677414E-05 0.0387640948619928"
        rpy="0 0 0" />
      <mass
        value="0.40723452931124" />
      <inertia
        ixx="9.69457560839621E-05"
        ixy="2.0410980070089E-06"
        ixz="7.58756661601313E-05"
        iyy="0.00700629137057798"
        iyz="-1.56447376402253E-07"
        izz="0.00702790486605186" />
    </inertial>
    <visual>
      <origin
        xyz="0 0 0"
        rpy="0 0 0" />
      <geometry>
        <mesh
          filename="package://second one/meshes/link_1.STL" />
      </geometry>
      <material
        name="">
        <color
          rgba="0.792156862745098 0.819607843137255 0.933333333333333 1" />
      </material>
    </visual>
    <collision>
      <origin
        xyz="0 0 0"
        rpy="0 0 0" />
      <geometry>
        <mesh
          filename="package://second one/meshes/link_1.STL" />
      </geometry>
    </collision>
  </link>
  <joint
    name="join_1"
    type="continuous">
    <origin
      xyz="0 0 0.0585999999999994"
      rpy="0 0 0" />
    <parent
      link="base_link" />
    <child
      link="link_1" />
    <axis
      xyz="0 0 1" />
  </joint>
  <link
    name="link_2">
    <inertial>
      <origin
        xyz="0.00196397351335068 -0.00186487970969972 0.0145490775115699"
        rpy="0 0 0" />
      <mass
        value="0.367769527757555" />
      <inertia
        ixx="0.00011625704154743"
        ixy="-5.14813183954665E-08"
        ixz="-2.57587248907994E-05"
        iyy="0.00523054388820953"
        iyz="-1.69348714943658E-07"
        izz="0.00529038024022097" />
    </inertial>
    <visual>
      <origin
        xyz="0 0 0"
        rpy="0 0 0" />
      <geometry>
        <mesh
          filename="package://second one/meshes/link_2.STL" />
      </geometry>
      <material
        name="">
        <color
          rgba="0.792156862745098 0.819607843137255 0.933333333333333 1" />
      </material>
    </visual>
    <collision>
      <origin
        xyz="0 0 0"
        rpy="0 0 0" />
      <geometry>
        <mesh
          filename="package://second one/meshes/link_2.STL" />
      </geometry>
    </collision>
  </link>
  <joint
    name="join_2"
    type="continuous">
    <origin
      xyz="0.20874229683865 0.00179332387615486 0.0588000000000003"
      rpy="0 0 0" />
    <parent
      link="link_1" />
    <child
      link="link_2" />
    <axis
      xyz="0 0 1" />
  </joint>
  <link
    name="end_effector">
    <inertial>
      <origin
        xyz="7.61978507484162E-05 0.00364583216276968 0.0165950058588744"
        rpy="0 0 0" />
      <mass
        value="0.00560645979584246" />
      <inertia
        ixx="4.03296465449601E-07"
        ixy="2.77072447095654E-09"
        ixz="1.11417467937036E-13"
        iyy="5.25753123312374E-07"
        iyz="3.40783016494575E-13"
        izz="2.59447001769474E-07" />
    </inertial>
    <visual>
      <origin
        xyz="0 0 0"
        rpy="0 0 0" />
      <geometry>
        <mesh
          filename="package://second one/meshes/end_effector.STL" />
      </geometry>
      <material
        name="">
        <color
          rgba="0.792156862745098 0.819607843137255 0.933333333333333 1" />
      </material>
    </visual>
    <collision>
      <origin
        xyz="0 0 0"
        rpy="0 0 0" />
      <geometry>
        <mesh
          filename="package://second one/meshes/end_effector.STL" />
      </geometry>
    </collision>
  </link>
  <joint
    name="joint_3"
    type="continuous">
    <origin
      xyz="0.21593150680297 -0.00543915156978894 0.0299998999999999"
      rpy="0 0 0" />
    <parent
      link="link_2" />
    <child
      link="end_effector" />
    <axis
      xyz="0 0 -1" />
  </joint>
</robot>